Workbook

Sheet Ownership
B2: Ownership
B4: Select Insiders | F4: (000s) | G4: %
A5: 1 | B5: =_xlfn.XLOOKUP(F5,$I$39:$I$178,$J$39:$J$178) | F5: =LARGE($I$39:$I$65,A5) | G5: =F5/$F$35
A6: 2 | B6: =_xlfn.XLOOKUP(F6,$I$39:$I$178,$J$39:$J$178) | F6: =LARGE($I$39:$I$65,A6) | G6: =F6/$F$35
A7: 3 | B7: =_xlfn.XLOOKUP(F7,$I$39:$I$178,$J$39:$J$178) | F7: =LARGE($I$39:$I$65,A7) | G7: =F7/$F$35
A8: 4 | B8: =_xlfn.XLOOKUP(F8,$I$39:$I$178,$J$39:$J$178) | F8: =LARGE($I$39:$I$65,A8) | G8: =F8/$F$35
A9: 5 | B9: =_xlfn.XLOOKUP(F9,$I$39:$I$178,$J$39:$J$178) | F9: =LARGE($I$39:$I$65,A9) | G9: =F9/$F$35
A10: 6 | B10: =_xlfn.XLOOKUP(F10,$I$39:$I$178,$J$39:$J$178) | F10: =LARGE($I$39:$I$65,A10) | G10: =F10/$F$35
A11: 7 | B11: =_xlfn.XLOOKUP(F11,$I$39:$I$178,$J$39:$J$178) | F11: =LARGE($I$39:$I$65,A11) | G11: =F11/$F$35
A12: 8 | B12: =_xlfn.XLOOKUP(F12,$I$39:$I$178,$J$39:$J$178) | F12: =LARGE($I$39:$I$65,A12) | G12: =F12/$F$35
A13: 9 | B13: =_xlfn.XLOOKUP(F13,$I$39:$I$178,$J$39:$J$178) | F13: =LARGE($I$39:$I$65,A13) | G13: =F13/$F$35
A14: 10 | B14: =_xlfn.XLOOKUP(F14,$I$39:$I$178,$J$39:$J$178) | F14: =LARGE($I$39:$I$65,A14) | G14: =F14/$F$35
A15: 11 | B15: =_xlfn.XLOOKUP(F15,$I$39:$I$178,$J$39:$J$178) | F15: =LARGE($I$39:$I$65,A15) | G15: =F15/$F$35
A16: 12 | B16: =_xlfn.XLOOKUP(F16,$I$39:$I$178,$J$39:$J$178) | F16: =LARGE($I$39:$I$65,A16) | G16: =F16/$F$35
B17: Subtotal | F17: =SUM(F5:F16) | G17: =F17/$F$35
B19: Select Institutions | F19: (000s) | G19: %
A20: 1 | B20: =_xlfn.XLOOKUP(F20,$I$39:$I$178,$J$39:$J$178) | F20: =LARGE($I$68:$I$185,A20) | G20: =F20/$F$35
A21: 2 | B21: =_xlfn.XLOOKUP(F21,$I$39:$I$178,$J$39:$J$178) | F21: =LARGE($I$68:$I$185,A21) | G21: =F21/$F$35
A22: 3 | B22: =_xlfn.XLOOKUP(F22,$I$39:$I$178,$J$39:$J$178) | F22: =LARGE($I$68:$I$185,A22) | G22: =F22/$F$35
A23: 4 | B23: =_xlfn.XLOOKUP(F23,$I$39:$I$178,$J$39:$J$178) | F23: =LARGE($I$68:$I$185,A23) | G23: =F23/$F$35
A24: 5 | B24: =_xlfn.XLOOKUP(F24,$I$39:$I$178,$J$39:$J$178) | F24: =LARGE($I$68:$I$185,A24) | G24: =F24/$F$35
A25: 6 | B25: =_xlfn.XLOOKUP(F25,$I$39:$I$178,$J$39:$J$178) | F25: =LARGE($I$68:$I$185,A25) | G25: =F25/$F$35
A26: 7 | B26: =_xlfn.XLOOKUP(F26,$I$39:$I$178,$J$39:$J$178) | F26: =LARGE($I$68:$I$185,A26) | G26: =F26/$F$35
A27: 8 | B27: =_xlfn.XLOOKUP(F27,$I$39:$I$178,$J$39:$J$178) | F27: =LARGE($I$68:$I$185,A27) | G27: =F27/$F$35
A28: 9 | B28: =_xlfn.XLOOKUP(F28,$I$39:$I$178,$J$39:$J$178) | F28: =LARGE($I$68:$I$185,A28) | G28: =F28/$F$35
A29: 10 | B29: =_xlfn.XLOOKUP(F29,$I$39:$I$178,$J$39:$J$178) | F29: =LARGE($I$68:$I$185,A29) | G29: =F29/$F$35
A30: 11 | B30: =_xlfn.XLOOKUP(F30,$I$39:$I$178,$J$39:$J$178) | F30: =LARGE($I$68:$I$185,A30) | G30: =F30/$F$35
A31: 12 | B31: =_xlfn.XLOOKUP(F31,$I$39:$I$178,$J$39:$J$178) | F31: =LARGE($I$68:$I$185,A31) | G31: =F31/$F$35
B32: Subtotal | F32: =SUM(F20:F31) | G32: =F32/$F$35
B33: Other Shareholders | F33: =+F35-F32-F17 | G33: =F33/$F$35
B35: Total Basic Shares Outstanding | G35: =F35/$F$35
B38: SEDI Name | F38: Basic | G38: Date | H38: Include | I38: Adj. # | J38: Adj. Name
H39: 1 | I39: =H39*F39
H40: 1 | I40: =H40*F40
H41: 1 | I41: =H41*F41
H42: 1 | I42: =H42*F42
H43: 1 | I43: =H43*F43
H44: 1 | I44: =H44*F44
H45: 1 | I45: =H45*F45
H46: 1 | I46: =H46*F46
...

Sheet Bloomberg Output
C7: Name
C9: Ticker | G9: View
C11: Sort By | G11: Order
C13: Holder Name | G13: Portfolio Name | L13: Position | M13: Latest Chg | N13: Filing Date | O13: Source | P13: % Out | Q13: % Portfolio | R13: Insider Status | S13: Institution Type | T13: Metro Area | U13: Country | V13: Market Value | W13: Hold Period | X13: Cost (FIFO) | Y13: Cost (LIFO) | Z13: Cost (Avg.) | AA13: Ret % (FIFO) | AB13: Ret % (LIFO) | AC13: Ret % (Avg)
B14: 1
B15: 2
B16: 3
B17: 4
B18: 5
B19: 6
B20: 7
B21: 8
B22: 9
B23: 10
B24: 11
B25: 12
... B131: 118
