Workbook
Name CAD_USD: captable!#REF!
Name infor_basic_shares: captable!$F$17
Name infor_cap_output_ccy: captable!$F$5
Name infor_cap_picture_range: captable!$B$15:$F$40
Name infor_cap_share_inputs: captable!$F$168:$F$185
Name infor_cap_ticker: captable!$F$3
Name infor_comps_group1_block: comps!$B$10:$AA$15
Name infor_comps_group1_label: comps!$D$9
Name infor_comps_group2_block: comps!$B$20:$AA$25
Name infor_comps_group2_label: comps!$D$19
Name infor_comps_group3_block: comps!$B$30:$AA$35
Name infor_comps_group3_label: comps!$D$29
Name infor_comps_output_ccy: comps!$F$3
Name infor_fx_rate: captable!$F$7
Name infor_ltm_ebitda_valuation: captable!$D$48
Name infor_ltm_revenue_valuation: captable!$D$47
Name infor_own_bbg_holder_block: 'Bloomberg Output'!$C$14:$AC$131
Name infor_own_bbg_link_block: Ownership!$H$68:$J$185
Name infor_own_insider_block: Ownership!$B$39:$J$65
Name infor_own_insiders_picture_range: Ownership!$B$4:$G$17
Name infor_own_institutions_picture_range: Ownership!$B$19:$G$35
Name infor_own_total_shares: Ownership!$F$35
Name infor_prec_group1_block: precedents!$B$8:$AI$13
Name infor_prec_group1_label: precedents!$E$7
Name infor_prec_group2_block: precedents!$B$17:$AI$22
Name infor_prec_group2_label: precedents!$E$16
Name infor_prec_output_ccy: precedents!$C$2
Name infor_share_price: captable!$F$16
Name IQ_CH: 110000
Name IQ_CQ: 5000
Name IQ_CY: 10000
Name IQ_DAILY: 500000
Name IQ_FH: 100000
Name IQ_FQ: 500
Name IQ_FY: 1000
Name IQ_LTM: 2000
Name IQ_MONTH: 15000
Name IQ_NTM: 6000
Name IQ_WEEK: 50000
Name IQ_YTD: 3000

Sheet captable
B2: Name: | F2: {=_xll.SNL.Clients.Office.Excel.Functions.SPG($F$3,"SP_COMPANY_NAME")} -> #NAME?
B3: Ticker:
B4: Input Currency: | F4: {=_xll.SNL.Clients.Office.Excel.Functions.SPG($F$3,"IQ_CURRENCY_FINANCIALS","FY0",$F$6,"Options: NA=NA")} -> #NAME?
B5: Output Currency: | F5: CAD
B6: Date: | F6: =TODAY()-1 -> 46230
B7: FX Rate:
B9: Toggles
B10: Dilutives Method: | F10: Treasury Stock
B11: Lease Toggle: | F11: ON
B13: =F2&" Cap Table" -> #NAME?
B15: Company Ticker: | F15: =F3 -> 0
B16: =CONCATENATE("Share Price (",TEXT(F6,"dd-mmm-yy"),")") -> Share Price (27-Jul-26)
B17: Basic Shares Outstanding | F17: =F186 -> 0
B18: Basic Market Cap | F18: =F16*F17 -> 0
B19: =IF(F10="Treasury Stock","Net","")&" ITM Dilutive Securities" -> Net ITM Dilutive Securities | F19: =IF(F10="Treasury Stock",F86,F84) -> #DIV/0!
B20: ITM Convertible Debentures | F20: =F104 -> 0
B21: Fully-Diluted Shares Outstanding | F21: =F17+F19+F20 -> #DIV/0!
B22: Fully-Diluted Market Cap | F22: =F16*F21 -> #DIV/0!
B24: Add: Debt | F24: =F122*F7 -> 0
B25: Add: Leases | F25: =IF($F$11="ON",$F$143,0)*F7 -> 0
B26: Less: Cash | F26: =-F164*F7 -> 0
B27: Less: Cash from ITM Proceeds | F27: =IF(F10="Treasury Stock",0,-F82)*F7 -> 0
B28: Net Debt | F28: =F24+F25+F26+F27 -> 0
B29: Preferred Shares | F29: =+$F$52*F7 -> 0
B30: Non-Controlling Interest | F30: =+$F$53*F7 -> 0
B31: Enterprise Value | F31: =F22+F28+F29+F30 -> #DIV/0!
B33: Financial Metrics | D33: LTM | E33: CY2026 | F33: CY2027
B34: Revenue | D34: =IFERROR(IF(D47="NULL","na ",D47),"n/a ") -> 0 | E34: =IFERROR(IF(E47="NULL","na ",E47),"n/a ") -> n/a | F34: =IFERROR(IF(F47="NULL","na ",F47),"n/a ") -> n/a
B35: Adj. EBITDA | D35: =IFERROR(IF(D48="NULL","na ",D48),"n/a ") -> 0 | E35: =IFERROR(IF(E48="NULL","na ",E48),"n/a ") -> n/a | F35: =IFERROR(IF(F48="NULL","na ",F48),"n/a ") -> n/a
B36: Adj. EBITDA Margin | D36: =IFERROR(IF(D35<0,"nmf ",D35/D34),"n/a ") -> n/a | E36: =IFERROR(IF(E35<0,"nmf ",E35/E34),"n/a ") -> n/a | F36: =IFERROR(IF(F35<0,"nmf ",F35/F34),"n/a ") -> n/a
B38: Valuation Metrics
B39: EV / Revenue | D39: =+$F$31/D$34 -> #DIV/0! | E39: =+$F$31/E$34 -> #DIV/0! | F39: =+$F$31/F$34 -> #DIV/0!
B40: EV / Adj. EBITDA | D40: =+$F$31/D$35 -> #DIV/0! | E40: =+$F$31/E$35 -> #DIV/0! | F40: =+$F$31/F$35 -> #DIV/0!
B42: Street Metrics
B43: Analyst Coverage (# of Analysts) | F43: {=_xll.SNL.Clients.Office.Excel.Functions.SPG($F$3,"SP_NUM_BROKER_REC",$F$6,"Options:NA=NA")} -> #NAME?
B44: Average Target Price | F44: {=_xll.SNL.Clients.Office.Excel.Functions.SPG($F$3,"SP_PRICE_TARGET",$F$6,"Options: NA=NA,Curr="&$F$4)} -> #NAME?
B45: % Upside vs. Current | F45: =IFERROR(F44/F16-1,"n/a ") -> n/a
B47: Revenue | E47: {=_xll.SNL.Clients.Office.Excel.Functions.SPG($F$3,"SP_REV_EST",E$33,$F$6,"Options:Mag=Millions,NA=NA,Curr="&$F$5)} -> #NAME? | F47: {=_xll.SNL.Clients.Office.Excel.Functions.SPG($F$3,"SP_REV_EST",F$33,$F$6,"Options:Mag=Millions,NA=NA,Curr="&$F$5)} -> #NAME?
B48: Adj. EBITDA | E48: {=_xll.SNL.Clients.Office.Excel.Functions.SPG($F$3,"SP_EBITDA_EST",E$33,$F$6,"Options:Mag=Millions,NA=NA,Curr="&$F$5)} -> #NAME? | F48: {=_xll.SNL.Clients.Office.Excel.Functions.SPG($F$3,"SP_EBITDA_EST",F$33,$F$6,"Options:Mag=Millions,NA=NA,Curr="&$F$5)} -> #NAME?
B50: I. Non-Controlling Interest & Preferred Shares
...

Sheet comps
E2: $F$2 | F2: =TODAY()-1 -> 46230 | L2: EV/Revenue | O2: EV/EBITDA
E3: Currency: | F3: CAD | K3: Min | L3: 0 | M3: 0 | N3: 0 | O3: 0 | P3: 0 | Q3: 0
E4: Period: | F4: 2026 | K4: Max | L4: 20 | M4: 20 | N4: 20 | O4: 50 | P4: 50 | Q4: 50
D6: ="(In "&IF(F3="USD","US","C")&"$MM, unless otherwise noted)" -> (In C$MM, unless otherwise noted) | G6: Price | H6: Price | I6: Native | J6: Market | K6: Enterprise | L6: EV / Revenue | O6: EV / EBITDA | R6: Rev. Growth | U6: P / E | X6: ROE | Y6: P / B | Z6: P / TBV | AC6: Revenue | AH6: EBITDA | AM6: EPS | AR6: ROE | AT6: BVPS | AV6: TBVPS | AX6: Div. | AY6: Book | BA6: Cash & ST | BE6: Gross Margin (%)
D7: Company | G7: =CONCATENATE("(",TEXT($F$2,"dd-mmm-yy"),")") -> (27-Jul-26) | H7: ="("&F3&")" -> (CAD) | I7: Currency | J7: Cap | K7: Value | L7: LTM | M7: ="CY"&$F$4&"E" -> CY2026E | N7: ="CY"&$F$4+1&"E" -> CY2027E | O7: LTM | P7: ="CY"&$F$4&"E" -> CY2026E | Q7: ="CY"&$F$4+1&"E" -> CY2027E | R7: =RIGHT(AD7,2)&"E-"&RIGHT(AE7,2)&"E" -> 25E-26E | S7: =RIGHT(AE7,2)&"E-"&RIGHT(AF7,2)&"E" -> 26E-27E | U7: LTM | V7: ="CY"&$F$4&"E" -> CY2026E | W7: ="CY"&$F$4+1&"E" -> CY2027E | X7: LTM | Y7: Current | Z7: Current | AA7: Description | AC7: LTM | AD7: ="CY"&$F$4-1 -> CY2025 | AE7: ="CY"&$F$4 -> CY2026 | AF7: ="CY"&$F$4+1 -> CY2027 | AH7: LTM | AI7: ="CY"&$F$4-1 -> CY2025 | AJ7: ="CY"&$F$4 -> CY2026 | AK7: ="CY"&$F$4+1 -> CY2027 | AM7: LTM | AN7: ="CY"&$F$4-1 -> CY2025 | AO7: ="CY"&$F$4 -> CY2026 | AP7: ="CY"&$F$4+1 -> CY2027 | AR7: LTM | AT7: LTM | AV7: LTM | AX7: Yield | AY7: Value | AZ7: Debt | BA7: Investments | BB7: Net Debt | BC7: Equity | BE7: LTM | BF7: ="CY"&$F$4-1 -> CY2025 | BG7: ="CY"&$F$4 -> CY2026 | BH7: ="CY"&$F$4+1 -> CY2027
BE8: \
D9: [Group #1]
D10: {=IF($B10="","",_xll.SNL.Clients.Office.Excel.Functions.SPG($B10, "SP_COMPANY_NAME"))} | G10: {=IF($B10="","",_xll.SNL.Clients.Office.Excel.Functions.SPG($B10,"SP_LASTSALEPRICE",WORKDAY($F$2+1,-1),"Options:Curr="&I10&",NA=--"))} | H10: {=IF($B10="","",_xll.SNL.Clients.Office.Excel.Functions.SPG($B10,"SP_PRICE_CLOSE",WORKDAY($F$2+1,-1),"Options:Curr="&$F$3&", NA=--"))} | I10: {=IF($B10="","",_xll.SNL.Clients.Office.Excel.Functions.SPG($B10,"SP_TRADING_CURRENCY","Options: NA=--"))} | J10: {=IF($B10="","n/a ",_xll.SNL.Clients.Office.Excel.Functions.SPG($B10,"SP_MARKETCAP",WORKDAY($F$2+1,-1),"Options:Curr="&$F$3&", Mag=Millions, NA=--"))} -> n/a | K10: {=IF($B10="","n/a ",_xll.SNL.Clients.Office.Excel.Functions.SPG($B10,"IQ_TEV",WORKDAY($F$2+1,-1),"Options:Curr="&$F$3&", Mag=Millions, NA=--"))} -> n/a | L10: =IFERROR(IF(OR($K10/AC10>L$4,$K10/AC10<L$3),"nmf ",$K10/AC10),"n/a ") -> n/a | M10: =IFERROR(IF(OR($K10/AE10>M$4,$K10/AE10<M$3),"nmf ",$K10/AE10),"n/a ") -> n/a | N10: =IFERROR(IF(OR($K10/AF10>N$4,$K10/AF10<N$3),"nmf ",$K10/AF10),"n/a ") -> n/a | O10: =IFERROR(IF(OR($K10/AH10>O$4,$K10/AH10<O$3),"nmf ",$K10/AH10),"n/a ") -> n/a | P10: =IFERROR(IF(OR($K10/AJ10>P$4,$K10/AJ10<P$3),"nmf ",$K10/AJ10),"n/a ") -> n/a | Q10: =IFERROR(IF(OR($K10/AK10>Q$4,$K10/AK10<Q$3),"nmf ",$K10/AK10),"n/a ") -> n/a | R10: =IFERROR((AE10/AD10)-1,"n/a ") -> n/a | S10: =IFERROR((AF10/AE10)-1,"n/a ") -> n/a | U10: =IFERROR($H10/AM10,"n/a ") -> n/a | V10: =IFERROR($H10/AO10,"n/a ") -> n/a | W10: =IFERROR($H10/AP10,"n/a ") -> n/a | X10: =IFERROR(AR10/100,"n/a ") -> n/a | Y10: =IFERROR(H10/AT10,"n/a ") -> n/a | Z10: =IFERROR(H10/AV10,"n/a ") -> n/a | AC10: {=IF($B10="","",_xll.SNL.Clients.Office.Excel.Functions.SPG($B10,"IQ_REV",AC$7,$F$2,"Options:Curr="&$F$3&", Mag=Millions, NA=--"))} | AD10: {=IF($B10="","",_xll.SNL.Clients.Office.Excel.Functions.SPG($B10,"SP_REV_EST",AD$7,$F$2,"Options:Curr="&$F$3&", Mag=Millions, NA=--"))} | AE10: {=IF($B10="","",_xll.SNL.Clients.Office.Excel.Functions.SPG($B10,"SP_REV_EST",AE$7,$F$2,"Options:Curr="&$F$3&", Mag=Millions, NA=--"))} | AF10: {=IF($B10="","",_xll.SNL.Clients.Office.Excel.Functions.SPG($B10,"SP_REV_EST",AF$7,$F$2,"Options:Curr="&$F$3&", Mag=Millions, NA=--"))} | AH10: {=IF($B10="","",_xll.SNL.Clients.Office.Excel.Functions.SPG($B10,"SP_EBITDA",AH$7,$F$2,"Options:Curr="&$F$3&", Mag=Millions, NA=--"))} | AI10: {=IF($B10="","",_xll.SNL.Clients.Office.Excel.Functions.SPG($B10,"SP_EBITDA_EST",AI$7,$F$2,"Options:Curr="&$F$3&", Mag=Millions, NA=--"))} | AJ10: {=IF($B10="","",_xll.SNL.Clients.Office.Excel.Functions.SPG($B10,"SP_EBITDA_EST",AJ$7,$F$2,"Options:Curr="&$F$3&", Mag=Millions, NA=--"))} | AK10: {=IF($B10="","",_xll.SNL.Clients.Office.Excel.Functions.SPG($B10,"SP_EBITDA_EST",AK$7,$F$2,"Options:Curr="&$F$3&", Mag=Millions, NA=--"))} | AM10: {=IF($B10="","",_xll.SNL.Clients.Office.Excel.Functions.SPG($B10,"IQ_BASIC_EPS_BEFORE_EXTRA",AM$7,$F$2,"Options:Curr="&$F$3&", NA=--"))} | AN10: {=IF($B10="","",_xll.SNL.Clients.Office.Excel.Functions.SPG($B10,"SP_EPS_EST",AN$7,$F$2,"Options:Curr="&$F$3&", NA=--"))} | AO10: {=IF($B10="","",_xll.SNL.Clients.Office.Excel.Functions.SPG($B10,"SP_EPS_EST",AO$7,$F$2,"Options:Curr="&$F$3&", NA=--"))} | AP10: {=IF($B10="","",_xll.SNL.Clients.Office.Excel.Functions.SPG($B10,"SP_EPS_EST",AP$7,$F$2,"Options:Curr="&$F$3&", NA=--"))} | AR10: {=IF($B10="","",_xll.SNL.Clients.Office.Excel.Functions.SPG($B10,"IQ_ROE",AR$7,$F$2,"Options:Curr="&$F$3&", NA=--"))} | AT10: {=IF($B10="","",_xll.SNL.Clients.Office.Excel.Functions.SPG($B10,"IQ_BVPS",AT$7,$F$2,"Options:Curr="&$F$3&", NA=--"))} | AV10: {=IF($B10="","",_xll.SNL.Clients.Office.Excel.Functions.SPG($B10,"IQ_TBVPS",AV$7,$F$2,"Options:Curr="&$F$3&", NA=--"))} | AX10: {=IF($B10="","",_xll.SNL.Clients.Office.Excel.Functions.SPG($B10,"SP_DIV_YIELD",WORKDAY($F$2+1,-1),"Options: NA=--"))} | AY10: {=IF($B10="","",_xll.SNL.Clients.Office.Excel.Functions.SPG($B10,"IQ_TOTAL_EQUITY","FQ0",$F$2,"Options:Curr="&$F$3&", Mag=Millions, NA=--"))} | AZ10: {=IF($B10="","",_xll.SNL.Clients.Office.Excel.Functions.SPG($B10,"IQ_TOTAL_DEBT","FQ0",$F$2,"Options:Curr="&$F$3&", Mag=Millions, NA=--"))} | BA10: {=IF($B10="","",_xll.SNL.Clients.Office.Excel.Functions.SPG($B10,"IQ_CASH_ST_INVEST","FQ0",$F$2,"Options:Curr="&$F$3&", Mag=Millions, NA=--"))} | BB10: =+AZ10-BA10 -> #VALUE! | BC10: {=IF($B10="","",_xll.SNL.Clients.Office.Excel.Functions.SPG($B10,"IQ_TOTAL_EQUITY","FQ0",$F$2,"Options:Curr="&$F$3&", Mag=Millions, NA=--"))} | BE10: =IF($B10="","",IFERROR(_xll.SNL.Clients.Office.Excel.Functions.SPG($B10,"SP_GROSS_MARGIN",BE$7,$F$2,"Options: NA=--")/100,"--")) | BF10: =IF($B10="","",IFERROR(_xll.SNL.Clients.Office.Excel.Functions.SPG($B10,"SP_GROSS_MARGIN_EST",BF$7,$F$2,"Options: NA=--")/100,"--")) | BG10: =IF($B10="","",IFERROR(_xll.SNL.Clients.Office.Excel.Functions.SPG($B10,"SP_GROSS_MARGIN_EST",BG$7,$F$2,"Options: NA=--")/100,"--")) | BH10: =IF($B10="","",IFERROR(_xll.SNL.Clients.Office.Excel.Functions.SPG($B10,"SP_GROSS_MARGIN_EST",BH$7,$F$2,"Options: NA=--")/100,"--"))
D11: {=IF($B11="","",_xll.SNL.Clients.Office.Excel.Functions.SPG($B11, "SP_COMPANY_NAME"))} | G11: {=IF($B11="","",_xll.SNL.Clients.Office.Excel.Functions.SPG($B11,"SP_LASTSALEPRICE",WORKDAY($F$2+1,-1),"Options:Curr="&I11&",NA=--"))} | H11: {=IF($B11="","",_xll.SNL.Clients.Office.Excel.Functions.SPG($B11,"SP_PRICE_CLOSE",WORKDAY($F$2+1,-1),"Options:Curr="&$F$3&", NA=--"))} | I11: {=IF($B11="","",_xll.SNL.Clients.Office.Excel.Functions.SPG($B11,"SP_TRADING_CURRENCY","Options: NA=--"))} | J11: {=IF($B11="","n/a ",_xll.SNL.Clients.Office.Excel.Functions.SPG($B11,"SP_MARKETCAP",WORKDAY($F$2+1,-1),"Options:Curr="&$F$3&", Mag=Millions, NA=--"))} -> n/a | K11: {=IF($B11="","n/a ",_xll.SNL.Clients.Office.Excel.Functions.SPG($B11,"IQ_TEV",WORKDAY($F$2+1,-1),"Options:Curr="&$F$3&", Mag=Millions, NA=--"))} -> n/a | L11: =IFERROR(IF(OR($K11/AC11>L$4,$K11/AC11<L$3),"nmf ",$K11/AC11),"n/a ") -> n/a | M11: =IFERROR(IF(OR($K11/AE11>M$4,$K11/AE11<M$3),"nmf ",$K11/AE11),"n/a ") -> n/a | N11: =IFERROR(IF(OR($K11/AF11>N$4,$K11/AF11<N$3),"nmf ",$K11/AF11),"n/a ") -> n/a | O11: =IFERROR(IF(OR($K11/AH11>O$4,$K11/AH11<O$3),"nmf ",$K11/AH11),"n/a ") -> n/a | P11: =IFERROR(IF(OR($K11/AJ11>P$4,$K11/AJ11<P$3),"nmf ",$K11/AJ11),"n/a ") -> n/a | Q11: =IFERROR(IF(OR($K11/AK11>Q$4,$K11/AK11<Q$3),"nmf ",$K11/AK11),"n/a ") -> n/a | R11: =IFERROR((AE11/AD11)-1,"n/a ") -> n/a | S11: =IFERROR((AF11/AE11)-1,"n/a ") -> n/a | U11: =IFERROR($H11/AM11,"n/a ") -> n/a | V11: =IFERROR($H11/AO11,"n/a ") -> n/a | W11: =IFERROR($H11/AP11,"n/a ") -> n/a | X11: =IFERROR(AR11/100,"n/a ") -> n/a | Y11: =IFERROR(H11/AT11,"n/a ") -> n/a | Z11: =IFERROR(H11/AV11,"n/a ") -> n/a | AC11: {=IF($B11="","",_xll.SNL.Clients.Office.Excel.Functions.SPG($B11,"IQ_REV",AC$7,$F$2,"Options:Curr="&$F$3&", Mag=Millions, NA=--"))} | AD11: {=IF($B11="","",_xll.SNL.Clients.Office.Excel.Functions.SPG($B11,"SP_REV_EST",AD$7,$F$2,"Options:Curr="&$F$3&", Mag=Millions, NA=--"))} | AE11: {=IF($B11="","",_xll.SNL.Clients.Office.Excel.Functions.SPG($B11,"SP_REV_EST",AE$7,$F$2,"Options:Curr="&$F$3&", Mag=Millions, NA=--"))} | AF11: {=IF($B11="","",_xll.SNL.Clients.Office.Excel.Functions.SPG($B11,"SP_REV_EST",AF$7,$F$2,"Options:Curr="&$F$3&", Mag=Millions, NA=--"))} | AH11: {=IF($B11="","",_xll.SNL.Clients.Office.Excel.Functions.SPG($B11,"SP_EBITDA",AH$7,$F$2,"Options:Curr="&$F$3&", Mag=Millions, NA=--"))} | AI11: {=IF($B11="","",_xll.SNL.Clients.Office.Excel.Functions.SPG($B11,"SP_EBITDA_EST",AI$7,$F$2,"Options:Curr="&$F$3&", Mag=Millions, NA=--"))} | AJ11: {=IF($B11="","",_xll.SNL.Clients.Office.Excel.Functions.SPG($B11,"SP_EBITDA_EST",AJ$7,$F$2,"Options:Curr="&$F$3&", Mag=Millions, NA=--"))} | AK11: {=IF($B11="","",_xll.SNL.Clients.Office.Excel.Functions.SPG($B11,"SP_EBITDA_EST",AK$7,$F$2,"Options:Curr="&$F$3&", Mag=Millions, NA=--"))} | AM11: {=IF($B11="","",_xll.SNL.Clients.Office.Excel.Functions.SPG($B11,"IQ_BASIC_EPS_BEFORE_EXTRA",AM$7,$F$2,"Options:Curr="&$F$3&", NA=--"))} | AN11: {=IF($B11="","",_xll.SNL.Clients.Office.Excel.Functions.SPG($B11,"SP_EPS_EST",AN$7,$F$2,"Options:Curr="&$F$3&", NA=--"))} | AO11: {=IF($B11="","",_xll.SNL.Clients.Office.Excel.Functions.SPG($B11,"SP_EPS_EST",AO$7,$F$2,"Options:Curr="&$F$3&", NA=--"))} | AP11: {=IF($B11="","",_xll.SNL.Clients.Office.Excel.Functions.SPG($B11,"SP_EPS_EST",AP$7,$F$2,"Options:Curr="&$F$3&", NA=--"))} | AR11: {=IF($B11="","",_xll.SNL.Clients.Office.Excel.Functions.SPG($B11,"IQ_ROE",AR$7,$F$2,"Options:Curr="&$F$3&", NA=--"))} | AT11: {=IF($B11="","",_xll.SNL.Clients.Office.Excel.Functions.SPG($B11,"IQ_BVPS",AT$7,$F$2,"Options:Curr="&$F$3&", NA=--"))} | AV11: {=IF($B11="","",_xll.SNL.Clients.Office.Excel.Functions.SPG($B11,"IQ_TBVPS",AV$7,$F$2,"Options:Curr="&$F$3&", NA=--"))} | AX11: {=IF($B11="","",_xll.SNL.Clients.Office.Excel.Functions.SPG($B11,"SP_DIV_YIELD",WORKDAY($F$2+1,-1),"Options: NA=--"))} | AY11: {=IF($B11="","",_xll.SNL.Clients.Office.Excel.Functions.SPG($B11,"IQ_TOTAL_EQUITY","FQ0",$F$2,"Options:Curr="&$F$3&", Mag=Millions, NA=--"))} | AZ11: {=IF($B11="","",_xll.SNL.Clients.Office.Excel.Functions.SPG($B11,"IQ_TOTAL_DEBT","FQ0",$F$2,"Options:Curr="&$F$3&", Mag=Millions, NA=--"))} | BA11: {=IF($B11="","",_xll.SNL.Clients.Office.Excel.Functions.SPG($B11,"IQ_CASH_ST_INVEST","FQ0",$F$2,"Options:Curr="&$F$3&", Mag=Millions, NA=--"))} | BB11: =+AZ11-BA11 -> #VALUE! | BC11: {=IF($B11="","",_xll.SNL.Clients.Office.Excel.Functions.SPG($B11,"IQ_TOTAL_EQUITY","FQ0",$F$2,"Options:Curr="&$F$3&", Mag=Millions, NA=--"))} | BE11: =IF($B11="","",IFERROR(_xll.SNL.Clients.Office.Excel.Functions.SPG($B11,"SP_GROSS_MARGIN",BE$7,$F$2,"Options: NA=--")/100,"--")) | BF11: =IF($B11="","",IFERROR(_xll.SNL.Clients.Office.Excel.Functions.SPG($B11,"SP_GROSS_MARGIN_EST",BF$7,$F$2,"Options: NA=--")/100,"--")) | BG11: =IF($B11="","",IFERROR(_xll.SNL.Clients.Office.Excel.Functions.SPG($B11,"SP_GROSS_MARGIN_EST",BG$7,$F$2,"Options: NA=--")/100,"--")) | BH11: =IF($B11="","",IFERROR(_xll.SNL.Clients.Office.Excel.Functions.SPG($B11,"SP_GROSS_MARGIN_EST",BH$7,$F$2,"Options: NA=--")/100,"--"))
D12: {=IF($B12="","",_xll.SNL.Clients.Office.Excel.Functions.SPG($B12, "SP_COMPANY_NAME"))} | G12: {=IF($B12="","",_xll.SNL.Clients.Office.Excel.Functions.SPG($B12,"SP_LASTSALEPRICE",WORKDAY($F$2+1,-1),"Options:Curr="&I12&",NA=--"))} | H12: {=IF($B12="","",_xll.SNL.Clients.Office.Excel.Functions.SPG($B12,"SP_PRICE_CLOSE",WORKDAY($F$2+1,-1),"Options:Curr="&$F$3&", NA=--"))} | I12: {=IF($B12="","",_xll.SNL.Clients.Office.Excel.Functions.SPG($B12,"SP_TRADING_CURRENCY","Options: NA=--"))} | J12: {=IF($B12="","n/a ",_xll.SNL.Clients.Office.Excel.Functions.SPG($B12,"SP_MARKETCAP",WORKDAY($F$2+1,-1),"Options:Curr="&$F$3&", Mag=Millions, NA=--"))} -> n/a | K12: {=IF($B12="","n/a ",_xll.SNL.Clients.Office.Excel.Functions.SPG($B12,"IQ_TEV",WORKDAY($F$2+1,-1),"Options:Curr="&$F$3&", Mag=Millions, NA=--"))} -> n/a | L12: =IFERROR(IF(OR($K12/AC12>L$4,$K12/AC12<L$3),"nmf ",$K12/AC12),"n/a ") -> n/a | M12: =IFERROR(IF(OR($K12/AE12>M$4,$K12/AE12<M$3),"nmf ",$K12/AE12),"n/a ") -> n/a | N12: =IFERROR(IF(OR($K12/AF12>N$4,$K12/AF12<N$3),"nmf ",$K12/AF12),"n/a ") -> n/a | O12: =IFERROR(IF(OR($K12/AH12>O$4,$K12/AH12<O$3),"nmf ",$K12/AH12),"n/a ") -> n/a | P12: =IFERROR(IF(OR($K12/AJ12>P$4,$K12/AJ12<P$3),"nmf ",$K12/AJ12),"n/a ") -> n/a | Q12: =IFERROR(IF(OR($K12/AK12>Q$4,$K12/AK12<Q$3),"nmf ",$K12/AK12),"n/a ") -> n/a | R12: =IFERROR((AE12/AD12)-1,"n/a ") -> n/a | S12: =IFERROR((AF12/AE12)-1,"n/a ") -> n/a | U12: =IFERROR($H12/AM12,"n/a ") -> n/a | V12: =IFERROR($H12/AO12,"n/a ") -> n/a | W12: =IFERROR($H12/AP12,"n/a ") -> n/a | X12: =IFERROR(AR12/100,"n/a ") -> n/a | Y12: =IFERROR(H12/AT12,"n/a ") -> n/a | Z12: =IFERROR(H12/AV12,"n/a ") -> n/a | AC12: {=IF($B12="","",_xll.SNL.Clients.Office.Excel.Functions.SPG($B12,"IQ_REV",AC$7,$F$2,"Options:Curr="&$F$3&", Mag=Millions, NA=--"))} | AD12: {=IF($B12="","",_xll.SNL.Clients.Office.Excel.Functions.SPG($B12,"SP_REV_EST",AD$7,$F$2,"Options:Curr="&$F$3&", Mag=Millions, NA=--"))} | AE12: {=IF($B12="","",_xll.SNL.Clients.Office.Excel.Functions.SPG($B12,"SP_REV_EST",AE$7,$F$2,"Options:Curr="&$F$3&", Mag=Millions, NA=--"))} | AF12: {=IF($B12="","",_xll.SNL.Clients.Office.Excel.Functions.SPG($B12,"SP_REV_EST",AF$7,$F$2,"Options:Curr="&$F$3&", Mag=Millions, NA=--"))} | AH12: {=IF($B12="","",_xll.SNL.Clients.Office.Excel.Functions.SPG($B12,"SP_EBITDA",AH$7,$F$2,"Options:Curr="&$F$3&", Mag=Millions, NA=--"))} | AI12: {=IF($B12="","",_xll.SNL.Clients.Office.Excel.Functions.SPG($B12,"SP_EBITDA_EST",AI$7,$F$2,"Options:Curr="&$F$3&", Mag=Millions, NA=--"))} | AJ12: {=IF($B12="","",_xll.SNL.Clients.Office.Excel.Functions.SPG($B12,"SP_EBITDA_EST",AJ$7,$F$2,"Options:Curr="&$F$3&", Mag=Millions, NA=--"))} | AK12: {=IF($B12="","",_xll.SNL.Clients.Office.Excel.Functions.SPG($B12,"SP_EBITDA_EST",AK$7,$F$2,"Options:Curr="&$F$3&", Mag=Millions, NA=--"))} | AM12: {=IF($B12="","",_xll.SNL.Clients.Office.Excel.Functions.SPG($B12,"IQ_BASIC_EPS_BEFORE_EXTRA",AM$7,$F$2,"Options:Curr="&$F$3&", NA=--"))} | AN12: {=IF($B12="","",_xll.SNL.Clients.Office.Excel.Functions.SPG($B12,"SP_EPS_EST",AN$7,$F$2,"Options:Curr="&$F$3&", NA=--"))} | AO12: {=IF($B12="","",_xll.SNL.Clients.Office.Excel.Functions.SPG($B12,"SP_EPS_EST",AO$7,$F$2,"Options:Curr="&$F$3&", NA=--"))} | AP12: {=IF($B12="","",_xll.SNL.Clients.Office.Excel.Functions.SPG($B12,"SP_EPS_EST",AP$7,$F$2,"Options:Curr="&$F$3&", NA=--"))} | AR12: {=IF($B12="","",_xll.SNL.Clients.Office.Excel.Functions.SPG($B12,"IQ_ROE",AR$7,$F$2,"Options:Curr="&$F$3&", NA=--"))} | AT12: {=IF($B12="","",_xll.SNL.Clients.Office.Excel.Functions.SPG($B12,"IQ_BVPS",AT$7,$F$2,"Options:Curr="&$F$3&", NA=--"))} | AV12: {=IF($B12="","",_xll.SNL.Clients.Office.Excel.Functions.SPG($B12,"IQ_TBVPS",AV$7,$F$2,"Options:Curr="&$F$3&", NA=--"))} | AX12: {=IF($B12="","",_xll.SNL.Clients.Office.Excel.Functions.SPG($B12,"SP_DIV_YIELD",WORKDAY($F$2+1,-1),"Options: NA=--"))} | AY12: {=IF($B12="","",_xll.SNL.Clients.Office.Excel.Functions.SPG($B12,"IQ_TOTAL_EQUITY","FQ0",$F$2,"Options:Curr="&$F$3&", Mag=Millions, NA=--"))} | AZ12: {=IF($B12="","",_xll.SNL.Clients.Office.Excel.Functions.SPG($B12,"IQ_TOTAL_DEBT","FQ0",$F$2,"Options:Curr="&$F$3&", Mag=Millions, NA=--"))} | BA12: {=IF($B12="","",_xll.SNL.Clients.Office.Excel.Functions.SPG($B12,"IQ_CASH_ST_INVEST","FQ0",$F$2,"Options:Curr="&$F$3&", Mag=Millions, NA=--"))} | BB12: =+AZ12-BA12 -> #VALUE! | BC12: {=IF($B12="","",_xll.SNL.Clients.Office.Excel.Functions.SPG($B12,"IQ_TOTAL_EQUITY","FQ0",$F$2,"Options:Curr="&$F$3&", Mag=Millions, NA=--"))} | BE12: =IF($B12="","",IFERROR(_xll.SNL.Clients.Office.Excel.Functions.SPG($B12,"SP_GROSS_MARGIN",BE$7,$F$2,"Options: NA=--")/100,"--")) | BF12: =IF($B12="","",IFERROR(_xll.SNL.Clients.Office.Excel.Functions.SPG($B12,"SP_GROSS_MARGIN_EST",BF$7,$F$2,"Options: NA=--")/100,"--")) | BG12: =IF($B12="","",IFERROR(_xll.SNL.Clients.Office.Excel.Functions.SPG($B12,"SP_GROSS_MARGIN_EST",BG$7,$F$2,"Options: NA=--")/100,"--")) | BH12: =IF($B12="","",IFERROR(_xll.SNL.Clients.Office.Excel.Functions.SPG($B12,"SP_GROSS_MARGIN_EST",BH$7,$F$2,"Options: NA=--")/100,"--"))
D13: {=IF($B13="","",_xll.SNL.Clients.Office.Excel.Functions.SPG($B13, "SP_COMPANY_NAME"))} | G13: {=IF($B13="","",_xll.SNL.Clients.Office.Excel.Functions.SPG($B13,"SP_LASTSALEPRICE",WORKDAY($F$2+1,-1),"Options:Curr="&I13&",NA=--"))} | H13: {=IF($B13="","",_xll.SNL.Clients.Office.Excel.Functions.SPG($B13,"SP_PRICE_CLOSE",WORKDAY($F$2+1,-1),"Options:Curr="&$F$3&", NA=--"))} | I13: {=IF($B13="","",_xll.SNL.Clients.Office.Excel.Functions.SPG($B13,"SP_TRADING_CURRENCY","Options: NA=--"))} | J13: {=IF($B13="","n/a ",_xll.SNL.Clients.Office.Excel.Functions.SPG($B13,"SP_MARKETCAP",WORKDAY($F$2+1,-1),"Options:Curr="&$F$3&", Mag=Millions, NA=--"))} -> n/a | K13: {=IF($B13="","n/a ",_xll.SNL.Clients.Office.Excel.Functions.SPG($B13,"IQ_TEV",WORKDAY($F$2+1,-1),"Options:Curr="&$F$3&", Mag=Millions, NA=--"))} -> n/a | L13: =IFERROR(IF(OR($K13/AC13>L$4,$K13/AC13<L$3),"nmf ",$K13/AC13),"n/a ") -> n/a | M13: =IFERROR(IF(OR($K13/AE13>M$4,$K13/AE13<M$3),"nmf ",$K13/AE13),"n/a ") -> n/a | N13: =IFERROR(IF(OR($K13/AF13>N$4,$K13/AF13<N$3),"nmf ",$K13/AF13),"n/a ") -> n/a | O13: =IFERROR(IF(OR($K13/AH13>O$4,$K13/AH13<O$3),"nmf ",$K13/AH13),"n/a ") -> n/a | P13: =IFERROR(IF(OR($K13/AJ13>P$4,$K13/AJ13<P$3),"nmf ",$K13/AJ13),"n/a ") -> n/a | Q13: =IFERROR(IF(OR($K13/AK13>Q$4,$K13/AK13<Q$3),"nmf ",$K13/AK13),"n/a ") -> n/a | R13: =IFERROR((AE13/AD13)-1,"n/a ") -> n/a | S13: =IFERROR((AF13/AE13)-1,"n/a ") -> n/a | U13: =IFERROR($H13/AM13,"n/a ") -> n/a | V13: =IFERROR($H13/AO13,"n/a ") -> n/a | W13: =IFERROR($H13/AP13,"n/a ") -> n/a | X13: =IFERROR(AR13/100,"n/a ") -> n/a | Y13: =IFERROR(H13/AT13,"n/a ") -> n/a | Z13: =IFERROR(H13/AV13,"n/a ") -> n/a | AC13: {=IF($B13="","",_xll.SNL.Clients.Office.Excel.Functions.SPG($B13,"IQ_REV",AC$7,$F$2,"Options:Curr="&$F$3&", Mag=Millions, NA=--"))} | AD13: {=IF($B13="","",_xll.SNL.Clients.Office.Excel.Functions.SPG($B13,"SP_REV_EST",AD$7,$F$2,"Options:Curr="&$F$3&", Mag=Millions, NA=--"))} | AE13: {=IF($B13="","",_xll.SNL.Clients.Office.Excel.Functions.SPG($B13,"SP_REV_EST",AE$7,$F$2,"Options:Curr="&$F$3&", Mag=Millions, NA=--"))} | AF13: {=IF($B13="","",_xll.SNL.Clients.Office.Excel.Functions.SPG($B13,"SP_REV_EST",AF$7,$F$2,"Options:Curr="&$F$3&", Mag=Millions, NA=--"))} | AH13: {=IF($B13="","",_xll.SNL.Clients.Office.Excel.Functions.SPG($B13,"SP_EBITDA",AH$7,$F$2,"Options:Curr="&$F$3&", Mag=Millions, NA=--"))} | AI13: {=IF($B13="","",_xll.SNL.Clients.Office.Excel.Functions.SPG($B13,"SP_EBITDA_EST",AI$7,$F$2,"Options:Curr="&$F$3&", Mag=Millions, NA=--"))} | AJ13: {=IF($B13="","",_xll.SNL.Clients.Office.Excel.Functions.SPG($B13,"SP_EBITDA_EST",AJ$7,$F$2,"Options:Curr="&$F$3&", Mag=Millions, NA=--"))} | AK13: {=IF($B13="","",_xll.SNL.Clients.Office.Excel.Functions.SPG($B13,"SP_EBITDA_EST",AK$7,$F$2,"Options:Curr="&$F$3&", Mag=Millions, NA=--"))} | AM13: {=IF($B13="","",_xll.SNL.Clients.Office.Excel.Functions.SPG($B13,"IQ_BASIC_EPS_BEFORE_EXTRA",AM$7,$F$2,"Options:Curr="&$F$3&", NA=--"))} | AN13: {=IF($B13="","",_xll.SNL.Clients.Office.Excel.Functions.SPG($B13,"SP_EPS_EST",AN$7,$F$2,"Options:Curr="&$F$3&", NA=--"))} | AO13: {=IF($B13="","",_xll.SNL.Clients.Office.Excel.Functions.SPG($B13,"SP_EPS_EST",AO$7,$F$2,"Options:Curr="&$F$3&", NA=--"))} | AP13: {=IF($B13="","",_xll.SNL.Clients.Office.Excel.Functions.SPG($B13,"SP_EPS_EST",AP$7,$F$2,"Options:Curr="&$F$3&", NA=--"))} | AR13: {=IF($B13="","",_xll.SNL.Clients.Office.Excel.Functions.SPG($B13,"IQ_ROE",AR$7,$F$2,"Options:Curr="&$F$3&", NA=--"))} | AT13: {=IF($B13="","",_xll.SNL.Clients.Office.Excel.Functions.SPG($B13,"IQ_BVPS",AT$7,$F$2,"Options:Curr="&$F$3&", NA=--"))} | AV13: {=IF($B13="","",_xll.SNL.Clients.Office.Excel.Functions.SPG($B13,"IQ_TBVPS",AV$7,$F$2,"Options:Curr="&$F$3&", NA=--"))} | AX13: {=IF($B13="","",_xll.SNL.Clients.Office.Excel.Functions.SPG($B13,"SP_DIV_YIELD",WORKDAY($F$2+1,-1),"Options: NA=--"))} | AY13: {=IF($B13="","",_xll.SNL.Clients.Office.Excel.Functions.SPG($B13,"IQ_TOTAL_EQUITY","FQ0",$F$2,"Options:Curr="&$F$3&", Mag=Millions, NA=--"))} | AZ13: {=IF($B13="","",_xll.SNL.Clients.Office.Excel.Functions.SPG($B13,"IQ_TOTAL_DEBT","FQ0",$F$2,"Options:Curr="&$F$3&", Mag=Millions, NA=--"))} | BA13: {=IF($B13="","",_xll.SNL.Clients.Office.Excel.Functions.SPG($B13,"IQ_CASH_ST_INVEST","FQ0",$F$2,"Options:Curr="&$F$3&", Mag=Millions, NA=--"))} | BB13: =+AZ13-BA13 -> #VALUE! | BC13: {=IF($B13="","",_xll.SNL.Clients.Office.Excel.Functions.SPG($B13,"IQ_TOTAL_EQUITY","FQ0",$F$2,"Options:Curr="&$F$3&", Mag=Millions, NA=--"))} | BE13: =IF($B13="","",IFERROR(_xll.SNL.Clients.Office.Excel.Functions.SPG($B13,"SP_GROSS_MARGIN",BE$7,$F$2,"Options: NA=--")/100,"--")) | BF13: =IF($B13="","",IFERROR(_xll.SNL.Clients.Office.Excel.Functions.SPG($B13,"SP_GROSS_MARGIN_EST",BF$7,$F$2,"Options: NA=--")/100,"--")) | BG13: =IF($B13="","",IFERROR(_xll.SNL.Clients.Office.Excel.Functions.SPG($B13,"SP_GROSS_MARGIN_EST",BG$7,$F$2,"Options: NA=--")/100,"--")) | BH13: =IF($B13="","",IFERROR(_xll.SNL.Clients.Office.Excel.Functions.SPG($B13,"SP_GROSS_MARGIN_EST",BH$7,$F$2,"Options: NA=--")/100,"--"))
D14: {=IF($B14="","",_xll.SNL.Clients.Office.Excel.Functions.SPG($B14, "SP_COMPANY_NAME"))} | G14: {=IF($B14="","",_xll.SNL.Clients.Office.Excel.Functions.SPG($B14,"SP_LASTSALEPRICE",WORKDAY($F$2+1,-1),"Options:Curr="&I14&",NA=--"))} | H14: {=IF($B14="","",_xll.SNL.Clients.Office.Excel.Functions.SPG($B14,"SP_PRICE_CLOSE",WORKDAY($F$2+1,-1),"Options:Curr="&$F$3&", NA=--"))} | I14: {=IF($B14="","",_xll.SNL.Clients.Office.Excel.Functions.SPG($B14,"SP_TRADING_CURRENCY","Options: NA=--"))} | J14: {=IF($B14="","n/a ",_xll.SNL.Clients.Office.Excel.Functions.SPG($B14,"SP_MARKETCAP",WORKDAY($F$2+1,-1),"Options:Curr="&$F$3&", Mag=Millions, NA=--"))} -> n/a | K14: {=IF($B14="","n/a ",_xll.SNL.Clients.Office.Excel.Functions.SPG($B14,"IQ_TEV",WORKDAY($F$2+1,-1),"Options:Curr="&$F$3&", Mag=Millions, NA=--"))} -> n/a | L14: =IFERROR(IF(OR($K14/AC14>L$4,$K14/AC14<L$3),"nmf ",$K14/AC14),"n/a ") -> n/a | M14: =IFERROR(IF(OR($K14/AE14>M$4,$K14/AE14<M$3),"nmf ",$K14/AE14),"n/a ") -> n/a | N14: =IFERROR(IF(OR($K14/AF14>N$4,$K14/AF14<N$3),"nmf ",$K14/AF14),"n/a ") -> n/a | O14: =IFERROR(IF(OR($K14/AH14>O$4,$K14/AH14<O$3),"nmf ",$K14/AH14),"n/a ") -> n/a | P14: =IFERROR(IF(OR($K14/AJ14>P$4,$K14/AJ14<P$3),"nmf ",$K14/AJ14),"n/a ") -> n/a | Q14: =IFERROR(IF(OR($K14/AK14>Q$4,$K14/AK14<Q$3),"nmf ",$K14/AK14),"n/a ") -> n/a | R14: =IFERROR((AE14/AD14)-1,"n/a ") -> n/a | S14: =IFERROR((AF14/AE14)-1,"n/a ") -> n/a | U14: =IFERROR($H14/AM14,"n/a ") -> n/a | V14: =IFERROR($H14/AO14,"n/a ") -> n/a | W14: =IFERROR($H14/AP14,"n/a ") -> n/a | X14: =IFERROR(AR14/100,"n/a ") -> n/a | Y14: =IFERROR(H14/AT14,"n/a ") -> n/a | Z14: =IFERROR(H14/AV14,"n/a ") -> n/a | AC14: {=IF($B14="","",_xll.SNL.Clients.Office.Excel.Functions.SPG($B14,"IQ_REV",AC$7,$F$2,"Options:Curr="&$F$3&", Mag=Millions, NA=--"))} | AD14: {=IF($B14="","",_xll.SNL.Clients.Office.Excel.Functions.SPG($B14,"SP_REV_EST",AD$7,$F$2,"Options:Curr="&$F$3&", Mag=Millions, NA=--"))} | AE14: {=IF($B14="","",_xll.SNL.Clients.Office.Excel.Functions.SPG($B14,"SP_REV_EST",AE$7,$F$2,"Options:Curr="&$F$3&", Mag=Millions, NA=--"))} | AF14: {=IF($B14="","",_xll.SNL.Clients.Office.Excel.Functions.SPG($B14,"SP_REV_EST",AF$7,$F$2,"Options:Curr="&$F$3&", Mag=Millions, NA=--"))} | AH14: {=IF($B14="","",_xll.SNL.Clients.Office.Excel.Functions.SPG($B14,"SP_EBITDA",AH$7,$F$2,"Options:Curr="&$F$3&", Mag=Millions, NA=--"))} | AI14: {=IF($B14="","",_xll.SNL.Clients.Office.Excel.Functions.SPG($B14,"SP_EBITDA_EST",AI$7,$F$2,"Options:Curr="&$F$3&", Mag=Millions, NA=--"))} | AJ14: {=IF($B14="","",_xll.SNL.Clients.Office.Excel.Functions.SPG($B14,"SP_EBITDA_EST",AJ$7,$F$2,"Options:Curr="&$F$3&", Mag=Millions, NA=--"))} | AK14: {=IF($B14="","",_xll.SNL.Clients.Office.Excel.Functions.SPG($B14,"SP_EBITDA_EST",AK$7,$F$2,"Options:Curr="&$F$3&", Mag=Millions, NA=--"))} | AM14: {=IF($B14="","",_xll.SNL.Clients.Office.Excel.Functions.SPG($B14,"IQ_BASIC_EPS_BEFORE_EXTRA",AM$7,$F$2,"Options:Curr="&$F$3&", NA=--"))} | AN14: {=IF($B14="","",_xll.SNL.Clients.Office.Excel.Functions.SPG($B14,"SP_EPS_EST",AN$7,$F$2,"Options:Curr="&$F$3&", NA=--"))} | AO14: {=IF($B14="","",_xll.SNL.Clients.Office.Excel.Functions.SPG($B14,"SP_EPS_EST",AO$7,$F$2,"Options:Curr="&$F$3&", NA=--"))} | AP14: {=IF($B14="","",_xll.SNL.Clients.Office.Excel.Functions.SPG($B14,"SP_EPS_EST",AP$7,$F$2,"Options:Curr="&$F$3&", NA=--"))} | AR14: {=IF($B14="","",_xll.SNL.Clients.Office.Excel.Functions.SPG($B14,"IQ_ROE",AR$7,$F$2,"Options:Curr="&$F$3&", NA=--"))} | AT14: {=IF($B14="","",_xll.SNL.Clients.Office.Excel.Functions.SPG($B14,"IQ_BVPS",AT$7,$F$2,"Options:Curr="&$F$3&", NA=--"))} | AV14: {=IF($B14="","",_xll.SNL.Clients.Office.Excel.Functions.SPG($B14,"IQ_TBVPS",AV$7,$F$2,"Options:Curr="&$F$3&", NA=--"))} | AX14: {=IF($B14="","",_xll.SNL.Clients.Office.Excel.Functions.SPG($B14,"SP_DIV_YIELD",WORKDAY($F$2+1,-1),"Options: NA=--"))} | AY14: {=IF($B14="","",_xll.SNL.Clients.Office.Excel.Functions.SPG($B14,"IQ_TOTAL_EQUITY","FQ0",$F$2,"Options:Curr="&$F$3&", Mag=Millions, NA=--"))} | AZ14: {=IF($B14="","",_xll.SNL.Clients.Office.Excel.Functions.SPG($B14,"IQ_TOTAL_DEBT","FQ0",$F$2,"Options:Curr="&$F$3&", Mag=Millions, NA=--"))} | BA14: {=IF($B14="","",_xll.SNL.Clients.Office.Excel.Functions.SPG($B14,"IQ_CASH_ST_INVEST","FQ0",$F$2,"Options:Curr="&$F$3&", Mag=Millions, NA=--"))} | BB14: =+AZ14-BA14 -> #VALUE! | BC14: {=IF($B14="","",_xll.SNL.Clients.Office.Excel.Functions.SPG($B14,"IQ_TOTAL_EQUITY","FQ0",$F$2,"Options:Curr="&$F$3&", Mag=Millions, NA=--"))} | BE14: =IF($B14="","",IFERROR(_xll.SNL.Clients.Office.Excel.Functions.SPG($B14,"SP_GROSS_MARGIN",BE$7,$F$2,"Options: NA=--")/100,"--")) | BF14: =IF($B14="","",IFERROR(_xll.SNL.Clients.Office.Excel.Functions.SPG($B14,"SP_GROSS_MARGIN_EST",BF$7,$F$2,"Options: NA=--")/100,"--")) | BG14: =IF($B14="","",IFERROR(_xll.SNL.Clients.Office.Excel.Functions.SPG($B14,"SP_GROSS_MARGIN_EST",BG$7,$F$2,"Options: NA=--")/100,"--")) | BH14: =IF($B14="","",IFERROR(_xll.SNL.Clients.Office.Excel.Functions.SPG($B14,"SP_GROSS_MARGIN_EST",BH$7,$F$2,"Options: NA=--")/100,"--"))
D15: {=IF($B15="","",_xll.SNL.Clients.Office.Excel.Functions.SPG($B15, "SP_COMPANY_NAME"))} | G15: {=IF($B15="","",_xll.SNL.Clients.Office.Excel.Functions.SPG($B15,"SP_LASTSALEPRICE",WORKDAY($F$2+1,-1),"Options:Curr="&I15&",NA=--"))} | H15: {=IF($B15="","",_xll.SNL.Clients.Office.Excel.Functions.SPG($B15,"SP_PRICE_CLOSE",WORKDAY($F$2+1,-1),"Options:Curr="&$F$3&", NA=--"))} | I15: {=IF($B15="","",_xll.SNL.Clients.Office.Excel.Functions.SPG($B15,"SP_TRADING_CURRENCY","Options: NA=--"))} | J15: {=IF($B15="","n/a ",_xll.SNL.Clients.Office.Excel.Functions.SPG($B15,"SP_MARKETCAP",WORKDAY($F$2+1,-1),"Options:Curr="&$F$3&", Mag=Millions, NA=--"))} -> n/a | K15: {=IF($B15="","n/a ",_xll.SNL.Clients.Office.Excel.Functions.SPG($B15,"IQ_TEV",WORKDAY($F$2+1,-1),"Options:Curr="&$F$3&", Mag=Millions, NA=--"))} -> n/a | L15: =IFERROR(IF(OR($K15/AC15>L$4,$K15/AC15<L$3),"nmf ",$K15/AC15),"n/a ") -> n/a | M15: =IFERROR(IF(OR($K15/AE15>M$4,$K15/AE15<M$3),"nmf ",$K15/AE15),"n/a ") -> n/a | N15: =IFERROR(IF(OR($K15/AF15>N$4,$K15/AF15<N$3),"nmf ",$K15/AF15),"n/a ") -> n/a | O15: =IFERROR(IF(OR($K15/AH15>O$4,$K15/AH15<O$3),"nmf ",$K15/AH15),"n/a ") -> n/a | P15: =IFERROR(IF(OR($K15/AJ15>P$4,$K15/AJ15<P$3),"nmf ",$K15/AJ15),"n/a ") -> n/a | Q15: =IFERROR(IF(OR($K15/AK15>Q$4,$K15/AK15<Q$3),"nmf ",$K15/AK15),"n/a ") -> n/a | R15: =IFERROR((AE15/AD15)-1,"n/a ") -> n/a | S15: =IFERROR((AF15/AE15)-1,"n/a ") -> n/a | U15: =IFERROR($H15/AM15,"n/a ") -> n/a | V15: =IFERROR($H15/AO15,"n/a ") -> n/a | W15: =IFERROR($H15/AP15,"n/a ") -> n/a | X15: =IFERROR(AR15/100,"n/a ") -> n/a | Y15: =IFERROR(H15/AT15,"n/a ") -> n/a | Z15: =IFERROR(H15/AV15,"n/a ") -> n/a | AC15: {=IF($B15="","",_xll.SNL.Clients.Office.Excel.Functions.SPG($B15,"IQ_REV",AC$7,$F$2,"Options:Curr="&$F$3&", Mag=Millions, NA=--"))} | AD15: {=IF($B15="","",_xll.SNL.Clients.Office.Excel.Functions.SPG($B15,"SP_REV_EST",AD$7,$F$2,"Options:Curr="&$F$3&", Mag=Millions, NA=--"))} | AE15: {=IF($B15="","",_xll.SNL.Clients.Office.Excel.Functions.SPG($B15,"SP_REV_EST",AE$7,$F$2,"Options:Curr="&$F$3&", Mag=Millions, NA=--"))} | AF15: {=IF($B15="","",_xll.SNL.Clients.Office.Excel.Functions.SPG($B15,"SP_REV_EST",AF$7,$F$2,"Options:Curr="&$F$3&", Mag=Millions, NA=--"))} | AH15: {=IF($B15="","",_xll.SNL.Clients.Office.Excel.Functions.SPG($B15,"SP_EBITDA",AH$7,$F$2,"Options:Curr="&$F$3&", Mag=Millions, NA=--"))} | AI15: {=IF($B15="","",_xll.SNL.Clients.Office.Excel.Functions.SPG($B15,"SP_EBITDA_EST",AI$7,$F$2,"Options:Curr="&$F$3&", Mag=Millions, NA=--"))} | AJ15: {=IF($B15="","",_xll.SNL.Clients.Office.Excel.Functions.SPG($B15,"SP_EBITDA_EST",AJ$7,$F$2,"Options:Curr="&$F$3&", Mag=Millions, NA=--"))} | AK15: {=IF($B15="","",_xll.SNL.Clients.Office.Excel.Functions.SPG($B15,"SP_EBITDA_EST",AK$7,$F$2,"Options:Curr="&$F$3&", Mag=Millions, NA=--"))} | AM15: {=IF($B15="","",_xll.SNL.Clients.Office.Excel.Functions.SPG($B15,"IQ_BASIC_EPS_BEFORE_EXTRA",AM$7,$F$2,"Options:Curr="&$F$3&", NA=--"))} | AN15: {=IF($B15="","",_xll.SNL.Clients.Office.Excel.Functions.SPG($B15,"SP_EPS_EST",AN$7,$F$2,"Options:Curr="&$F$3&", NA=--"))} | AO15: {=IF($B15="","",_xll.SNL.Clients.Office.Excel.Functions.SPG($B15,"SP_EPS_EST",AO$7,$F$2,"Options:Curr="&$F$3&", NA=--"))} | AP15: {=IF($B15="","",_xll.SNL.Clients.Office.Excel.Functions.SPG($B15,"SP_EPS_EST",AP$7,$F$2,"Options:Curr="&$F$3&", NA=--"))} | AR15: {=IF($B15="","",_xll.SNL.Clients.Office.Excel.Functions.SPG($B15,"IQ_ROE",AR$7,$F$2,"Options:Curr="&$F$3&", NA=--"))} | AT15: {=IF($B15="","",_xll.SNL.Clients.Office.Excel.Functions.SPG($B15,"IQ_BVPS",AT$7,$F$2,"Options:Curr="&$F$3&", NA=--"))} | AV15: {=IF($B15="","",_xll.SNL.Clients.Office.Excel.Functions.SPG($B15,"IQ_TBVPS",AV$7,$F$2,"Options:Curr="&$F$3&", NA=--"))} | AX15: {=IF($B15="","",_xll.SNL.Clients.Office.Excel.Functions.SPG($B15,"SP_DIV_YIELD",WORKDAY($F$2+1,-1),"Options: NA=--"))} | AY15: {=IF($B15="","",_xll.SNL.Clients.Office.Excel.Functions.SPG($B15,"IQ_TOTAL_EQUITY","FQ0",$F$2,"Options:Curr="&$F$3&", Mag=Millions, NA=--"))} | AZ15: {=IF($B15="","",_xll.SNL.Clients.Office.Excel.Functions.SPG($B15,"IQ_TOTAL_DEBT","FQ0",$F$2,"Options:Curr="&$F$3&", Mag=Millions, NA=--"))} | BA15: {=IF($B15="","",_xll.SNL.Clients.Office.Excel.Functions.SPG($B15,"IQ_CASH_ST_INVEST","FQ0",$F$2,"Options:Curr="&$F$3&", Mag=Millions, NA=--"))} | BB15: =+AZ15-BA15 -> #VALUE! | BC15: {=IF($B15="","",_xll.SNL.Clients.Office.Excel.Functions.SPG($B15,"IQ_TOTAL_EQUITY","FQ0",$F$2,"Options:Curr="&$F$3&", Mag=Millions, NA=--"))} | BE15: =IF($B15="","",IFERROR(_xll.SNL.Clients.Office.Excel.Functions.SPG($B15,"SP_GROSS_MARGIN",BE$7,$F$2,"Options: NA=--")/100,"--")) | BF15: =IF($B15="","",IFERROR(_xll.SNL.Clients.Office.Excel.Functions.SPG($B15,"SP_GROSS_MARGIN_EST",BF$7,$F$2,"Options: NA=--")/100,"--")) | BG15: =IF($B15="","",IFERROR(_xll.SNL.Clients.Office.Excel.Functions.SPG($B15,"SP_GROSS_MARGIN_EST",BG$7,$F$2,"Options: NA=--")/100,"--")) | BH15: =IF($B15="","",IFERROR(_xll.SNL.Clients.Office.Excel.Functions.SPG($B15,"SP_GROSS_MARGIN_EST",BH$7,$F$2,"Options: NA=--")/100,"--"))
D17: Group Average | L17: =IFERROR(AVERAGE(L10:L15),"n/a ") -> n/a | M17: =IFERROR(AVERAGE(M10:M15),"n/a ") -> n/a | N17: =IFERROR(AVERAGE(N10:N15),"n/a ") -> n/a | O17: =IFERROR(AVERAGE(O10:O15),"n/a ") -> n/a | P17: =IFERROR(AVERAGE(P10:P15),"n/a ") -> n/a | Q17: =IFERROR(AVERAGE(Q10:Q15),"n/a ") -> n/a | R17: =IFERROR(AVERAGE(R10:R15),"n/a ") -> n/a | S17: =IFERROR(AVERAGE(S10:S15),"n/a ") -> n/a | U17: =IFERROR(AVERAGE(U10:U15),"n/a ") -> n/a | V17: =IFERROR(AVERAGE(V10:V15),"n/a ") -> n/a | W17: =IFERROR(AVERAGE(W10:W15),"n/a ") -> n/a | X17: =IFERROR(AVERAGE(X10:X15),"n/a ") -> n/a | Y17: =IFERROR(AVERAGE(Y10:Y15),"n/a ") -> n/a | Z17: =IFERROR(AVERAGE(Z10:Z15),"n/a ") -> n/a
D19: [Group #2]
D20: {=IF($B20="","",_xll.SNL.Clients.Office.Excel.Functions.SPG($B20, "SP_COMPANY_NAME"))} | G20: {=IF($B20="","",_xll.SNL.Clients.Office.Excel.Functions.SPG($B20,"SP_LASTSALEPRICE",WORKDAY($F$2+1,-1),"Options:Curr="&I20&",NA=--"))} | H20: {=IF($B20="","",_xll.SNL.Clients.Office.Excel.Functions.SPG($B20,"SP_PRICE_CLOSE",WORKDAY($F$2+1,-1),"Options:Curr="&$F$3&", NA=--"))} | I20: {=IF($B20="","",_xll.SNL.Clients.Office.Excel.Functions.SPG($B20,"SP_TRADING_CURRENCY","Options: NA=--"))} | J20: {=IF($B20="","n/a ",_xll.SNL.Clients.Office.Excel.Functions.SPG($B20,"SP_MARKETCAP",WORKDAY($F$2+1,-1),"Options:Curr="&$F$3&", Mag=Millions, NA=--"))} -> n/a | K20: {=IF($B20="","n/a ",_xll.SNL.Clients.Office.Excel.Functions.SPG($B20,"IQ_TEV",WORKDAY($F$2+1,-1),"Options:Curr="&$F$3&", Mag=Millions, NA=--"))} -> n/a | L20: =IFERROR(IF(OR($K20/AC20>L$4,$K20/AC20<L$3),"nmf ",$K20/AC20),"n/a ") -> n/a | M20: =IFERROR(IF(OR($K20/AD20>M$4,$K20/AD20<M$3),"nmf ",$K20/AD20),"n/a ") -> n/a | N20: =IFERROR(IF(OR($K20/AE20>N$4,$K20/AE20<N$3),"nmf ",$K20/AE20),"n/a ") -> n/a | O20: =IFERROR(IF(OR($K20/AH20>O$4,$K20/AH20<O$3),"nmf ",$K20/AH20),"n/a ") -> n/a | P20: =IFERROR(IF(OR($K20/AI20>P$4,$K20/AI20<P$3),"nmf ",$K20/AI20),"n/a ") -> n/a | Q20: =IFERROR(IF(OR($K20/AJ20>Q$4,$K20/AJ20<Q$3),"nmf ",$K20/AJ20),"n/a ") -> n/a | R20: =IFERROR((AE20/AD20)-1,"n/a ") -> n/a | S20: =IFERROR((AF20/AE20)-1,"n/a ") -> n/a | U20: =IFERROR($H20/AM20,"n/a ") -> n/a | V20: =IFERROR($H20/AO20,"n/a ") -> n/a | W20: =IFERROR($H20/AP20,"n/a ") -> n/a | X20: =IFERROR(AR20/100,"n/a ") -> n/a | Y20: =IFERROR(H20/AT20,"n/a ") -> n/a | Z20: =IFERROR(H20/AV20,"n/a ") -> n/a | AC20: {=IF($B20="","",_xll.SNL.Clients.Office.Excel.Functions.SPG($B20,"IQ_REV",AC$7,$F$2,"Options:Curr="&$F$3&", Mag=Millions, NA=--"))} | AD20: {=IF($B20="","",_xll.SNL.Clients.Office.Excel.Functions.SPG($B20,"SP_REV_EST",AD$7,$F$2,"Options:Curr="&$F$3&", Mag=Millions, NA=--"))} | AE20: {=IF($B20="","",_xll.SNL.Clients.Office.Excel.Functions.SPG($B20,"SP_REV_EST",AE$7,$F$2,"Options:Curr="&$F$3&", Mag=Millions, NA=--"))} | AF20: {=IF($B20="","",_xll.SNL.Clients.Office.Excel.Functions.SPG($B20,"SP_REV_EST",AF$7,$F$2,"Options:Curr="&$F$3&", Mag=Millions, NA=--"))} | AH20: {=IF($B20="","",_xll.SNL.Clients.Office.Excel.Functions.SPG($B20,"SP_EBITDA",AH$7,$F$2,"Options:Curr="&$F$3&", Mag=Millions, NA=--"))} | AI20: {=IF($B20="","",_xll.SNL.Clients.Office.Excel.Functions.SPG($B20,"SP_EBITDA_EST",AI$7,$F$2,"Options:Curr="&$F$3&", Mag=Millions, NA=--"))} | AJ20: {=IF($B20="","",_xll.SNL.Clients.Office.Excel.Functions.SPG($B20,"SP_EBITDA_EST",AJ$7,$F$2,"Options:Curr="&$F$3&", Mag=Millions, NA=--"))} | AK20: {=IF($B20="","",_xll.SNL.Clients.Office.Excel.Functions.SPG($B20,"SP_EBITDA_EST",AK$7,$F$2,"Options:Curr="&$F$3&", Mag=Millions, NA=--"))} | AM20: {=IF($B20="","",_xll.SNL.Clients.Office.Excel.Functions.SPG($B20,"IQ_BASIC_EPS_BEFORE_EXTRA",AM$7,$F$2,"Options:Curr="&$F$3&", NA=--"))} | AN20: {=IF($B20="","",_xll.SNL.Clients.Office.Excel.Functions.SPG($B20,"SP_EPS_EST",AN$7,$F$2,"Options:Curr="&$F$3&", NA=--"))} | AO20: {=IF($B20="","",_xll.SNL.Clients.Office.Excel.Functions.SPG($B20,"SP_EPS_EST",AO$7,$F$2,"Options:Curr="&$F$3&", NA=--"))} | AP20: {=IF($B20="","",_xll.SNL.Clients.Office.Excel.Functions.SPG($B20,"SP_EPS_EST",AP$7,$F$2,"Options:Curr="&$F$3&", NA=--"))} | AR20: {=IF($B20="","",_xll.SNL.Clients.Office.Excel.Functions.SPG($B20,"IQ_ROE",AR$7,$F$2,"Options:Curr="&$F$3&", NA=--"))} | AT20: {=IF($B20="","",_xll.SNL.Clients.Office.Excel.Functions.SPG($B20,"IQ_BVPS",AT$7,$F$2,"Options:Curr="&$F$3&", NA=--"))} | AV20: {=IF($B20="","",_xll.SNL.Clients.Office.Excel.Functions.SPG($B20,"IQ_TBVPS",AV$7,$F$2,"Options:Curr="&$F$3&", NA=--"))} | AX20: {=IF($B20="","",_xll.SNL.Clients.Office.Excel.Functions.SPG($B20,"SP_DIV_YIELD",WORKDAY($F$2+1,-1),"Options: NA=--"))} | AY20: {=IF($B20="","",_xll.SNL.Clients.Office.Excel.Functions.SPG($B20,"IQ_TOTAL_EQUITY","FQ0",$F$2,"Options:Curr="&$F$3&", Mag=Millions, NA=--"))} | AZ20: {=IF($B20="","",_xll.SNL.Clients.Office.Excel.Functions.SPG($B20,"IQ_TOTAL_DEBT","FQ0",$F$2,"Options:Curr="&$F$3&", Mag=Millions, NA=--"))} | BA20: {=IF($B20="","",_xll.SNL.Clients.Office.Excel.Functions.SPG($B20,"IQ_CASH_ST_INVEST","FQ0",$F$2,"Options:Curr="&$F$3&", Mag=Millions, NA=--"))} | BB20: =+AZ20-BA20 -> #VALUE! | BC20: {=IF($B20="","",_xll.SNL.Clients.Office.Excel.Functions.SPG($B20,"IQ_TOTAL_EQUITY","FQ0",$F$2,"Options:Curr="&$F$3&", Mag=Millions, NA=--"))} | BE20: =IF($B20="","",IFERROR(_xll.SNL.Clients.Office.Excel.Functions.SPG($B20,"SP_GROSS_MARGIN",BE$7,$F$2,"Options: NA=--")/100,"--")) | BF20: =IF($B20="","",IFERROR(_xll.SNL.Clients.Office.Excel.Functions.SPG($B20,"SP_GROSS_MARGIN_EST",BF$7,$F$2,"Options: NA=--")/100,"--")) | BG20: =IF($B20="","",IFERROR(_xll.SNL.Clients.Office.Excel.Functions.SPG($B20,"SP_GROSS_MARGIN_EST",BG$7,$F$2,"Options: NA=--")/100,"--")) | BH20: =IF($B20="","",IFERROR(_xll.SNL.Clients.Office.Excel.Functions.SPG($B20,"SP_GROSS_MARGIN_EST",BH$7,$F$2,"Options: NA=--")/100,"--"))
D21: {=IF($B21="","",_xll.SNL.Clients.Office.Excel.Functions.SPG($B21, "SP_COMPANY_NAME"))} | G21: {=IF($B21="","",_xll.SNL.Clients.Office.Excel.Functions.SPG($B21,"SP_LASTSALEPRICE",WORKDAY($F$2+1,-1),"Options:Curr="&I21&",NA=--"))} | H21: {=IF($B21="","",_xll.SNL.Clients.Office.Excel.Functions.SPG($B21,"SP_PRICE_CLOSE",WORKDAY($F$2+1,-1),"Options:Curr="&$F$3&", NA=--"))} | I21: {=IF($B21="","",_xll.SNL.Clients.Office.Excel.Functions.SPG($B21,"SP_TRADING_CURRENCY","Options: NA=--"))} | J21: {=IF($B21="","n/a ",_xll.SNL.Clients.Office.Excel.Functions.SPG($B21,"SP_MARKETCAP",WORKDAY($F$2+1,-1),"Options:Curr="&$F$3&", Mag=Millions, NA=--"))} -> n/a | K21: {=IF($B21="","n/a ",_xll.SNL.Clients.Office.Excel.Functions.SPG($B21,"IQ_TEV",WORKDAY($F$2+1,-1),"Options:Curr="&$F$3&", Mag=Millions, NA=--"))} -> n/a | L21: =IFERROR(IF(OR($K21/AC21>L$4,$K21/AC21<L$3),"nmf ",$K21/AC21),"n/a ") -> n/a | M21: =IFERROR(IF(OR($K21/AD21>M$4,$K21/AD21<M$3),"nmf ",$K21/AD21),"n/a ") -> n/a | N21: =IFERROR(IF(OR($K21/AE21>N$4,$K21/AE21<N$3),"nmf ",$K21/AE21),"n/a ") -> n/a | O21: =IFERROR(IF(OR($K21/AH21>O$4,$K21/AH21<O$3),"nmf ",$K21/AH21),"n/a ") -> n/a | P21: =IFERROR(IF(OR($K21/AI21>P$4,$K21/AI21<P$3),"nmf ",$K21/AI21),"n/a ") -> n/a | Q21: =IFERROR(IF(OR($K21/AJ21>Q$4,$K21/AJ21<Q$3),"nmf ",$K21/AJ21),"n/a ") -> n/a | R21: =IFERROR((AE21/AD21)-1,"n/a ") -> n/a | S21: =IFERROR((AF21/AE21)-1,"n/a ") -> n/a | U21: =IFERROR($H21/AM21,"n/a ") -> n/a | V21: =IFERROR($H21/AO21,"n/a ") -> n/a | W21: =IFERROR($H21/AP21,"n/a ") -> n/a | X21: =IFERROR(AR21/100,"n/a ") -> n/a | Y21: =IFERROR(H21/AT21,"n/a ") -> n/a | Z21: =IFERROR(H21/AV21,"n/a ") -> n/a | AC21: {=IF($B21="","",_xll.SNL.Clients.Office.Excel.Functions.SPG($B21,"IQ_REV",AC$7,$F$2,"Options:Curr="&$F$3&", Mag=Millions, NA=--"))} | AD21: {=IF($B21="","",_xll.SNL.Clients.Office.Excel.Functions.SPG($B21,"SP_REV_EST",AD$7,$F$2,"Options:Curr="&$F$3&", Mag=Millions, NA=--"))} | AE21: {=IF($B21="","",_xll.SNL.Clients.Office.Excel.Functions.SPG($B21,"SP_REV_EST",AE$7,$F$2,"Options:Curr="&$F$3&", Mag=Millions, NA=--"))} | AF21: {=IF($B21="","",_xll.SNL.Clients.Office.Excel.Functions.SPG($B21,"SP_REV_EST",AF$7,$F$2,"Options:Curr="&$F$3&", Mag=Millions, NA=--"))} | AH21: {=IF($B21="","",_xll.SNL.Clients.Office.Excel.Functions.SPG($B21,"SP_EBITDA",AH$7,$F$2,"Options:Curr="&$F$3&", Mag=Millions, NA=--"))} | AI21: {=IF($B21="","",_xll.SNL.Clients.Office.Excel.Functions.SPG($B21,"SP_EBITDA_EST",AI$7,$F$2,"Options:Curr="&$F$3&", Mag=Millions, NA=--"))} | AJ21: {=IF($B21="","",_xll.SNL.Clients.Office.Excel.Functions.SPG($B21,"SP_EBITDA_EST",AJ$7,$F$2,"Options:Curr="&$F$3&", Mag=Millions, NA=--"))} | AK21: {=IF($B21="","",_xll.SNL.Clients.Office.Excel.Functions.SPG($B21,"SP_EBITDA_EST",AK$7,$F$2,"Options:Curr="&$F$3&", Mag=Millions, NA=--"))} | AM21: {=IF($B21="","",_xll.SNL.Clients.Office.Excel.Functions.SPG($B21,"IQ_BASIC_EPS_BEFORE_EXTRA",AM$7,$F$2,"Options:Curr="&$F$3&", NA=--"))} | AN21: {=IF($B21="","",_xll.SNL.Clients.Office.Excel.Functions.SPG($B21,"SP_EPS_EST",AN$7,$F$2,"Options:Curr="&$F$3&", NA=--"))} | AO21: {=IF($B21="","",_xll.SNL.Clients.Office.Excel.Functions.SPG($B21,"SP_EPS_EST",AO$7,$F$2,"Options:Curr="&$F$3&", NA=--"))} | AP21: {=IF($B21="","",_xll.SNL.Clients.Office.Excel.Functions.SPG($B21,"SP_EPS_EST",AP$7,$F$2,"Options:Curr="&$F$3&", NA=--"))} | AR21: {=IF($B21="","",_xll.SNL.Clients.Office.Excel.Functions.SPG($B21,"IQ_ROE",AR$7,$F$2,"Options:Curr="&$F$3&", NA=--"))} | AT21: {=IF($B21="","",_xll.SNL.Clients.Office.Excel.Functions.SPG($B21,"IQ_BVPS",AT$7,$F$2,"Options:Curr="&$F$3&", NA=--"))} | AV21: {=IF($B21="","",_xll.SNL.Clients.Office.Excel.Functions.SPG($B21,"IQ_TBVPS",AV$7,$F$2,"Options:Curr="&$F$3&", NA=--"))} | AX21: {=IF($B21="","",_xll.SNL.Clients.Office.Excel.Functions.SPG($B21,"SP_DIV_YIELD",WORKDAY($F$2+1,-1),"Options: NA=--"))} | AY21: {=IF($B21="","",_xll.SNL.Clients.Office.Excel.Functions.SPG($B21,"IQ_TOTAL_EQUITY","FQ0",$F$2,"Options:Curr="&$F$3&", Mag=Millions, NA=--"))} | AZ21: {=IF($B21="","",_xll.SNL.Clients.Office.Excel.Functions.SPG($B21,"IQ_TOTAL_DEBT","FQ0",$F$2,"Options:Curr="&$F$3&", Mag=Millions, NA=--"))} | BA21: {=IF($B21="","",_xll.SNL.Clients.Office.Excel.Functions.SPG($B21,"IQ_CASH_ST_INVEST","FQ0",$F$2,"Options:Curr="&$F$3&", Mag=Millions, NA=--"))} | BB21: =+AZ21-BA21 -> #VALUE! | BC21: {=IF($B21="","",_xll.SNL.Clients.Office.Excel.Functions.SPG($B21,"IQ_TOTAL_EQUITY","FQ0",$F$2,"Options:Curr="&$F$3&", Mag=Millions, NA=--"))} | BE21: =IF($B21="","",IFERROR(_xll.SNL.Clients.Office.Excel.Functions.SPG($B21,"SP_GROSS_MARGIN",BE$7,$F$2,"Options: NA=--")/100,"--")) | BF21: =IF($B21="","",IFERROR(_xll.SNL.Clients.Office.Excel.Functions.SPG($B21,"SP_GROSS_MARGIN_EST",BF$7,$F$2,"Options: NA=--")/100,"--")) | BG21: =IF($B21="","",IFERROR(_xll.SNL.Clients.Office.Excel.Functions.SPG($B21,"SP_GROSS_MARGIN_EST",BG$7,$F$2,"Options: NA=--")/100,"--")) | BH21: =IF($B21="","",IFERROR(_xll.SNL.Clients.Office.Excel.Functions.SPG($B21,"SP_GROSS_MARGIN_EST",BH$7,$F$2,"Options: NA=--")/100,"--"))
D22: {=IF($B22="","",_xll.SNL.Clients.Office.Excel.Functions.SPG($B22, "SP_COMPANY_NAME"))} | G22: {=IF($B22="","",_xll.SNL.Clients.Office.Excel.Functions.SPG($B22,"SP_LASTSALEPRICE",WORKDAY($F$2+1,-1),"Options:Curr="&I22&",NA=--"))} | H22: {=IF($B22="","",_xll.SNL.Clients.Office.Excel.Functions.SPG($B22,"SP_PRICE_CLOSE",WORKDAY($F$2+1,-1),"Options:Curr="&$F$3&", NA=--"))} | I22: {=IF($B22="","",_xll.SNL.Clients.Office.Excel.Functions.SPG($B22,"SP_TRADING_CURRENCY","Options: NA=--"))} | J22: {=IF($B22="","n/a ",_xll.SNL.Clients.Office.Excel.Functions.SPG($B22,"SP_MARKETCAP",WORKDAY($F$2+1,-1),"Options:Curr="&$F$3&", Mag=Millions, NA=--"))} -> n/a | K22: {=IF($B22="","n/a ",_xll.SNL.Clients.Office.Excel.Functions.SPG($B22,"IQ_TEV",WORKDAY($F$2+1,-1),"Options:Curr="&$F$3&", Mag=Millions, NA=--"))} -> n/a | L22: =IFERROR(IF(OR($K22/AC22>L$4,$K22/AC22<L$3),"nmf ",$K22/AC22),"n/a ") -> n/a | M22: =IFERROR(IF(OR($K22/AD22>M$4,$K22/AD22<M$3),"nmf ",$K22/AD22),"n/a ") -> n/a | N22: =IFERROR(IF(OR($K22/AE22>N$4,$K22/AE22<N$3),"nmf ",$K22/AE22),"n/a ") -> n/a | O22: =IFERROR(IF(OR($K22/AH22>O$4,$K22/AH22<O$3),"nmf ",$K22/AH22),"n/a ") -> n/a | P22: =IFERROR(IF(OR($K22/AI22>P$4,$K22/AI22<P$3),"nmf ",$K22/AI22),"n/a ") -> n/a | Q22: =IFERROR(IF(OR($K22/AJ22>Q$4,$K22/AJ22<Q$3),"nmf ",$K22/AJ22),"n/a ") -> n/a | R22: =IFERROR((AE22/AD22)-1,"n/a ") -> n/a | S22: =IFERROR((AF22/AE22)-1,"n/a ") -> n/a | U22: =IFERROR($H22/AM22,"n/a ") -> n/a | V22: =IFERROR($H22/AO22,"n/a ") -> n/a | W22: =IFERROR($H22/AP22,"n/a ") -> n/a | X22: =IFERROR(AR22/100,"n/a ") -> n/a | Y22: =IFERROR(H22/AT22,"n/a ") -> n/a | Z22: =IFERROR(H22/AV22,"n/a ") -> n/a | AC22: {=IF($B22="","",_xll.SNL.Clients.Office.Excel.Functions.SPG($B22,"IQ_REV",AC$7,$F$2,"Options:Curr="&$F$3&", Mag=Millions, NA=--"))} | AD22: {=IF($B22="","",_xll.SNL.Clients.Office.Excel.Functions.SPG($B22,"SP_REV_EST",AD$7,$F$2,"Options:Curr="&$F$3&", Mag=Millions, NA=--"))} | AE22: {=IF($B22="","",_xll.SNL.Clients.Office.Excel.Functions.SPG($B22,"SP_REV_EST",AE$7,$F$2,"Options:Curr="&$F$3&", Mag=Millions, NA=--"))} | AF22: {=IF($B22="","",_xll.SNL.Clients.Office.Excel.Functions.SPG($B22,"SP_REV_EST",AF$7,$F$2,"Options:Curr="&$F$3&", Mag=Millions, NA=--"))} | AH22: {=IF($B22="","",_xll.SNL.Clients.Office.Excel.Functions.SPG($B22,"SP_EBITDA",AH$7,$F$2,"Options:Curr="&$F$3&", Mag=Millions, NA=--"))} | AI22: {=IF($B22="","",_xll.SNL.Clients.Office.Excel.Functions.SPG($B22,"SP_EBITDA_EST",AI$7,$F$2,"Options:Curr="&$F$3&", Mag=Millions, NA=--"))} | AJ22: {=IF($B22="","",_xll.SNL.Clients.Office.Excel.Functions.SPG($B22,"SP_EBITDA_EST",AJ$7,$F$2,"Options:Curr="&$F$3&", Mag=Millions, NA=--"))} | AK22: {=IF($B22="","",_xll.SNL.Clients.Office.Excel.Functions.SPG($B22,"SP_EBITDA_EST",AK$7,$F$2,"Options:Curr="&$F$3&", Mag=Millions, NA=--"))} | AM22: {=IF($B22="","",_xll.SNL.Clients.Office.Excel.Functions.SPG($B22,"IQ_BASIC_EPS_BEFORE_EXTRA",AM$7,$F$2,"Options:Curr="&$F$3&", NA=--"))} | AN22: {=IF($B22="","",_xll.SNL.Clients.Office.Excel.Functions.SPG($B22,"SP_EPS_EST",AN$7,$F$2,"Options:Curr="&$F$3&", NA=--"))} | AO22: {=IF($B22="","",_xll.SNL.Clients.Office.Excel.Functions.SPG($B22,"SP_EPS_EST",AO$7,$F$2,"Options:Curr="&$F$3&", NA=--"))} | AP22: {=IF($B22="","",_xll.SNL.Clients.Office.Excel.Functions.SPG($B22,"SP_EPS_EST",AP$7,$F$2,"Options:Curr="&$F$3&", NA=--"))} | AR22: {=IF($B22="","",_xll.SNL.Clients.Office.Excel.Functions.SPG($B22,"IQ_ROE",AR$7,$F$2,"Options:Curr="&$F$3&", NA=--"))} | AT22: {=IF($B22="","",_xll.SNL.Clients.Office.Excel.Functions.SPG($B22,"IQ_BVPS",AT$7,$F$2,"Options:Curr="&$F$3&", NA=--"))} | AV22: {=IF($B22="","",_xll.SNL.Clients.Office.Excel.Functions.SPG($B22,"IQ_TBVPS",AV$7,$F$2,"Options:Curr="&$F$3&", NA=--"))} | AX22: {=IF($B22="","",_xll.SNL.Clients.Office.Excel.Functions.SPG($B22,"SP_DIV_YIELD",WORKDAY($F$2+1,-1),"Options: NA=--"))} | AY22: {=IF($B22="","",_xll.SNL.Clients.Office.Excel.Functions.SPG($B22,"IQ_TOTAL_EQUITY","FQ0",$F$2,"Options:Curr="&$F$3&", Mag=Millions, NA=--"))} | AZ22: {=IF($B22="","",_xll.SNL.Clients.Office.Excel.Functions.SPG($B22,"IQ_TOTAL_DEBT","FQ0",$F$2,"Options:Curr="&$F$3&", Mag=Millions, NA=--"))} | BA22: {=IF($B22="","",_xll.SNL.Clients.Office.Excel.Functions.SPG($B22,"IQ_CASH_ST_INVEST","FQ0",$F$2,"Options:Curr="&$F$3&", Mag=Millions, NA=--"))} | BB22: =+AZ22-BA22 -> #VALUE! | BC22: {=IF($B22="","",_xll.SNL.Clients.Office.Excel.Functions.SPG($B22,"IQ_TOTAL_EQUITY","FQ0",$F$2,"Options:Curr="&$F$3&", Mag=Millions, NA=--"))} | BE22: =IF($B22="","",IFERROR(_xll.SNL.Clients.Office.Excel.Functions.SPG($B22,"SP_GROSS_MARGIN",BE$7,$F$2,"Options: NA=--")/100,"--")) | BF22: =IF($B22="","",IFERROR(_xll.SNL.Clients.Office.Excel.Functions.SPG($B22,"SP_GROSS_MARGIN_EST",BF$7,$F$2,"Options: NA=--")/100,"--")) | BG22: =IF($B22="","",IFERROR(_xll.SNL.Clients.Office.Excel.Functions.SPG($B22,"SP_GROSS_MARGIN_EST",BG$7,$F$2,"Options: NA=--")/100,"--")) | BH22: =IF($B22="","",IFERROR(_xll.SNL.Clients.Office.Excel.Functions.SPG($B22,"SP_GROSS_MARGIN_EST",BH$7,$F$2,"Options: NA=--")/100,"--"))
D23: {=IF($B23="","",_xll.SNL.Clients.Office.Excel.Functions.SPG($B23, "SP_COMPANY_NAME"))} | G23: {=IF($B23="","",_xll.SNL.Clients.Office.Excel.Functions.SPG($B23,"SP_LASTSALEPRICE",WORKDAY($F$2+1,-1),"Options:Curr="&I23&",NA=--"))} | H23: {=IF($B23="","",_xll.SNL.Clients.Office.Excel.Functions.SPG($B23,"SP_PRICE_CLOSE",WORKDAY($F$2+1,-1),"Options:Curr="&$F$3&", NA=--"))} | I23: {=IF($B23="","",_xll.SNL.Clients.Office.Excel.Functions.SPG($B23,"SP_TRADING_CURRENCY","Options: NA=--"))} | J23: {=IF($B23="","n/a ",_xll.SNL.Clients.Office.Excel.Functions.SPG($B23,"SP_MARKETCAP",WORKDAY($F$2+1,-1),"Options:Curr="&$F$3&", Mag=Millions, NA=--"))} -> n/a | K23: {=IF($B23="","n/a ",_xll.SNL.Clients.Office.Excel.Functions.SPG($B23,"IQ_TEV",WORKDAY($F$2+1,-1),"Options:Curr="&$F$3&", Mag=Millions, NA=--"))} -> n/a | L23: =IFERROR(IF(OR($K23/AC23>L$4,$K23/AC23<L$3),"nmf ",$K23/AC23),"n/a ") -> n/a | M23: =IFERROR(IF(OR($K23/AD23>M$4,$K23/AD23<M$3),"nmf ",$K23/AD23),"n/a ") -> n/a | N23: =IFERROR(IF(OR($K23/AE23>N$4,$K23/AE23<N$3),"nmf ",$K23/AE23),"n/a ") -> n/a | O23: =IFERROR(IF(OR($K23/AH23>O$4,$K23/AH23<O$3),"nmf ",$K23/AH23),"n/a ") -> n/a | P23: =IFERROR(IF(OR($K23/AI23>P$4,$K23/AI23<P$3),"nmf ",$K23/AI23),"n/a ") -> n/a | Q23: =IFERROR(IF(OR($K23/AJ23>Q$4,$K23/AJ23<Q$3),"nmf ",$K23/AJ23),"n/a ") -> n/a | R23: =IFERROR((AE23/AD23)-1,"n/a ") -> n/a | S23: =IFERROR((AF23/AE23)-1,"n/a ") -> n/a | U23: =IFERROR($H23/AM23,"n/a ") -> n/a | V23: =IFERROR($H23/AO23,"n/a ") -> n/a | W23: =IFERROR($H23/AP23,"n/a ") -> n/a | X23: =IFERROR(AR23/100,"n/a ") -> n/a | Y23: =IFERROR(H23/AT23,"n/a ") -> n/a | Z23: =IFERROR(H23/AV23,"n/a ") -> n/a | AC23: {=IF($B23="","",_xll.SNL.Clients.Office.Excel.Functions.SPG($B23,"IQ_REV",AC$7,$F$2,"Options:Curr="&$F$3&", Mag=Millions, NA=--"))} | AD23: {=IF($B23="","",_xll.SNL.Clients.Office.Excel.Functions.SPG($B23,"SP_REV_EST",AD$7,$F$2,"Options:Curr="&$F$3&", Mag=Millions, NA=--"))} | AE23: {=IF($B23="","",_xll.SNL.Clients.Office.Excel.Functions.SPG($B23,"SP_REV_EST",AE$7,$F$2,"Options:Curr="&$F$3&", Mag=Millions, NA=--"))} | AF23: {=IF($B23="","",_xll.SNL.Clients.Office.Excel.Functions.SPG($B23,"SP_REV_EST",AF$7,$F$2,"Options:Curr="&$F$3&", Mag=Millions, NA=--"))} | AH23: {=IF($B23="","",_xll.SNL.Clients.Office.Excel.Functions.SPG($B23,"SP_EBITDA",AH$7,$F$2,"Options:Curr="&$F$3&", Mag=Millions, NA=--"))} | AI23: {=IF($B23="","",_xll.SNL.Clients.Office.Excel.Functions.SPG($B23,"SP_EBITDA_EST",AI$7,$F$2,"Options:Curr="&$F$3&", Mag=Millions, NA=--"))} | AJ23: {=IF($B23="","",_xll.SNL.Clients.Office.Excel.Functions.SPG($B23,"SP_EBITDA_EST",AJ$7,$F$2,"Options:Curr="&$F$3&", Mag=Millions, NA=--"))} | AK23: {=IF($B23="","",_xll.SNL.Clients.Office.Excel.Functions.SPG($B23,"SP_EBITDA_EST",AK$7,$F$2,"Options:Curr="&$F$3&", Mag=Millions, NA=--"))} | AM23: {=IF($B23="","",_xll.SNL.Clients.Office.Excel.Functions.SPG($B23,"IQ_BASIC_EPS_BEFORE_EXTRA",AM$7,$F$2,"Options:Curr="&$F$3&", NA=--"))} | AN23: {=IF($B23="","",_xll.SNL.Clients.Office.Excel.Functions.SPG($B23,"SP_EPS_EST",AN$7,$F$2,"Options:Curr="&$F$3&", NA=--"))} | AO23: {=IF($B23="","",_xll.SNL.Clients.Office.Excel.Functions.SPG($B23,"SP_EPS_EST",AO$7,$F$2,"Options:Curr="&$F$3&", NA=--"))} | AP23: {=IF($B23="","",_xll.SNL.Clients.Office.Excel.Functions.SPG($B23,"SP_EPS_EST",AP$7,$F$2,"Options:Curr="&$F$3&", NA=--"))} | AR23: {=IF($B23="","",_xll.SNL.Clients.Office.Excel.Functions.SPG($B23,"IQ_ROE",AR$7,$F$2,"Options:Curr="&$F$3&", NA=--"))} | AT23: {=IF($B23="","",_xll.SNL.Clients.Office.Excel.Functions.SPG($B23,"IQ_BVPS",AT$7,$F$2,"Options:Curr="&$F$3&", NA=--"))} | AV23: {=IF($B23="","",_xll.SNL.Clients.Office.Excel.Functions.SPG($B23,"IQ_TBVPS",AV$7,$F$2,"Options:Curr="&$F$3&", NA=--"))} | AX23: {=IF($B23="","",_xll.SNL.Clients.Office.Excel.Functions.SPG($B23,"SP_DIV_YIELD",WORKDAY($F$2+1,-1),"Options: NA=--"))} | AY23: {=IF($B23="","",_xll.SNL.Clients.Office.Excel.Functions.SPG($B23,"IQ_TOTAL_EQUITY","FQ0",$F$2,"Options:Curr="&$F$3&", Mag=Millions, NA=--"))} | AZ23: {=IF($B23="","",_xll.SNL.Clients.Office.Excel.Functions.SPG($B23,"IQ_TOTAL_DEBT","FQ0",$F$2,"Options:Curr="&$F$3&", Mag=Millions, NA=--"))} | BA23: {=IF($B23="","",_xll.SNL.Clients.Office.Excel.Functions.SPG($B23,"IQ_CASH_ST_INVEST","FQ0",$F$2,"Options:Curr="&$F$3&", Mag=Millions, NA=--"))} | BB23: =+AZ23-BA23 -> #VALUE! | BC23: {=IF($B23="","",_xll.SNL.Clients.Office.Excel.Functions.SPG($B23,"IQ_TOTAL_EQUITY","FQ0",$F$2,"Options:Curr="&$F$3&", Mag=Millions, NA=--"))} | BE23: =IF($B23="","",IFERROR(_xll.SNL.Clients.Office.Excel.Functions.SPG($B23,"SP_GROSS_MARGIN",BE$7,$F$2,"Options: NA=--")/100,"--")) | BF23: =IF($B23="","",IFERROR(_xll.SNL.Clients.Office.Excel.Functions.SPG($B23,"SP_GROSS_MARGIN_EST",BF$7,$F$2,"Options: NA=--")/100,"--")) | BG23: =IF($B23="","",IFERROR(_xll.SNL.Clients.Office.Excel.Functions.SPG($B23,"SP_GROSS_MARGIN_EST",BG$7,$F$2,"Options: NA=--")/100,"--")) | BH23: =IF($B23="","",IFERROR(_xll.SNL.Clients.Office.Excel.Functions.SPG($B23,"SP_GROSS_MARGIN_EST",BH$7,$F$2,"Options: NA=--")/100,"--"))
